2022-06-06 16:50:27,704 INFO    MainThread:16588 [internal.py:wandb_internal():93] W&B internal server running at pid: 16588, started at: 2022-06-06 16:50:27.703133
2022-06-06 16:50:28,360 DEBUG   SenderThread:16588 [sender.py:send():232] send: header
2022-06-06 16:50:28,360 INFO    WriterThread:16588 [datastore.py:open_for_write():75] open: C:\Users\nicol\Documents\Academics\Spring2022\TCSS556\KGAT-pytorch\wandb\run-20220606_165020-1xt0y846\run-1xt0y846.wandb
2022-06-06 16:50:28,364 DEBUG   SenderThread:16588 [sender.py:send():232] send: run
2022-06-06 16:50:28,520 ERROR   SenderThread:16588 [internal_api.py:execute():143] 404 response executing GraphQL.
2022-06-06 16:50:28,520 ERROR   SenderThread:16588 [internal_api.py:execute():144] {"errors":[{"message":"project not found","path":["upsertBucket"]}],"data":{"upsertBucket":null}}
2022-06-06 16:50:31,438 INFO    WriterThread:16588 [datastore.py:close():279] close: C:\Users\nicol\Documents\Academics\Spring2022\TCSS556\KGAT-pytorch\wandb\run-20220606_165020-1xt0y846\run-1xt0y846.wandb
2022-06-06 16:50:31,439 INFO    HandlerThread:16588 [handler.py:finish():806] shutting down handler
2022-06-06 16:50:31,439 ERROR   MainThread:16588 [internal.py:wandb_internal():165] Thread SenderThread:
Traceback (most recent call last):
  File "C:\Users\nicol\Anaconda3\envs\kgat-pytorch\lib\site-packages\wandb\sdk\lib\retry.py", line 102, in __call__
    result = self._call_fn(*args, **kwargs)
  File "C:\Users\nicol\Anaconda3\envs\kgat-pytorch\lib\site-packages\wandb\sdk\internal\internal_api.py", line 140, in execute
    return self.client.execute(*args, **kwargs)
  File "C:\Users\nicol\Anaconda3\envs\kgat-pytorch\lib\site-packages\wandb\vendor\gql-0.2.0\wandb_gql\client.py", line 52, in execute
    result = self._get_result(document, *args, **kwargs)
  File "C:\Users\nicol\Anaconda3\envs\kgat-pytorch\lib\site-packages\wandb\vendor\gql-0.2.0\wandb_gql\client.py", line 60, in _get_result
    return self.transport.execute(document, *args, **kwargs)
  File "C:\Users\nicol\Anaconda3\envs\kgat-pytorch\lib\site-packages\wandb\vendor\gql-0.2.0\wandb_gql\transport\requests.py", line 39, in execute
    request.raise_for_status()
  File "C:\Users\nicol\Anaconda3\envs\kgat-pytorch\lib\site-packages\requests\models.py", line 960, in raise_for_status
    raise HTTPError(http_error_msg, response=self)
requests.exceptions.HTTPError: 404 Client Error: Not Found for url: https://api.wandb.ai/graphql

During handling of the above exception, another exception occurred:

Traceback (most recent call last):
  File "C:\Users\nicol\Anaconda3\envs\kgat-pytorch\lib\site-packages\wandb\apis\normalize.py", line 22, in wrapper
    return func(*args, **kwargs)
  File "C:\Users\nicol\Anaconda3\envs\kgat-pytorch\lib\site-packages\wandb\sdk\internal\internal_api.py", line 1319, in upsert_run
    response = self.gql(mutation, variable_values=variable_values, **kwargs)
  File "C:\Users\nicol\Anaconda3\envs\kgat-pytorch\lib\site-packages\wandb\sdk\lib\retry.py", line 118, in __call__
    if not check_retry_fn(e):
  File "C:\Users\nicol\Anaconda3\envs\kgat-pytorch\lib\site-packages\wandb\util.py", line 882, in no_retry_auth
    raise CommError("Permission denied, ask the project owner to grant you access")
wandb.errors.CommError: Permission denied, ask the project owner to grant you access

During handling of the above exception, another exception occurred:

Traceback (most recent call last):
  File "C:\Users\nicol\Anaconda3\envs\kgat-pytorch\lib\site-packages\wandb\sdk\internal\internal_util.py", line 51, in run
    self._run()
  File "C:\Users\nicol\Anaconda3\envs\kgat-pytorch\lib\site-packages\wandb\sdk\internal\internal_util.py", line 102, in _run
    self._process(record)
  File "C:\Users\nicol\Anaconda3\envs\kgat-pytorch\lib\site-packages\wandb\sdk\internal\internal.py", line 310, in _process
    self._sm.send(record)
  File "C:\Users\nicol\Anaconda3\envs\kgat-pytorch\lib\site-packages\wandb\sdk\internal\sender.py", line 234, in send
    send_handler(record)
  File "C:\Users\nicol\Anaconda3\envs\kgat-pytorch\lib\site-packages\wandb\sdk\internal\sender.py", line 692, in send_run
    self._init_run(run, config_value_dict)
  File "C:\Users\nicol\Anaconda3\envs\kgat-pytorch\lib\site-packages\wandb\sdk\internal\sender.py", line 730, in _init_run
    commit=run.git.last_commit or None,
  File "C:\Users\nicol\Anaconda3\envs\kgat-pytorch\lib\site-packages\wandb\apis\normalize.py", line 58, in wrapper
    raise CommError(message, err).with_traceback(sys.exc_info()[2])
  File "C:\Users\nicol\Anaconda3\envs\kgat-pytorch\lib\site-packages\wandb\apis\normalize.py", line 22, in wrapper
    return func(*args, **kwargs)
  File "C:\Users\nicol\Anaconda3\envs\kgat-pytorch\lib\site-packages\wandb\sdk\internal\internal_api.py", line 1319, in upsert_run
    response = self.gql(mutation, variable_values=variable_values, **kwargs)
  File "C:\Users\nicol\Anaconda3\envs\kgat-pytorch\lib\site-packages\wandb\sdk\lib\retry.py", line 118, in __call__
    if not check_retry_fn(e):
  File "C:\Users\nicol\Anaconda3\envs\kgat-pytorch\lib\site-packages\wandb\util.py", line 882, in no_retry_auth
    raise CommError("Permission denied, ask the project owner to grant you access")
wandb.errors.CommError: Permission denied, ask the project owner to grant you access
2022-06-06 16:50:38,502 INFO    MainThread:16588 [internal.py:handle_exit():80] Internal process exited
